Workbook

Sheet Início
A1: 4º SEMESTRE — PAINEL DE NOTAS
A2: Insper | 2026-1 | Atualizado automaticamente com as notas inseridas em cada aba
A4: Matéria | B4: Professor(es) | C4: MF Atual | D4: Situação | E4: Prova Final
A5: Econometria | B5: Bortoluzzo / Martins | C5: =IF(ISNUMBER('Econometria'!C18),'Econometria'!C18,"—") | D5: =IF(C5="—","—",IF(C5>=5,"✓ Aprovado","Em andamento")) | E5: 27/05/2026
A6: Estatística II | B6: M.Kelly / Rinaldo | C6: =IF(ISNUMBER('Estatística II'!C16),'Estatística II'!C16,"—") | D6: =IF(C6="—","—",IF(C6>=5,"✓ Aprovado","Em andamento")) | E6: 27/05/2026
A7: Finanças II | B7: G.Soares / P.Neto | C7: =IF(ISNUMBER('Finanças II'!C19),'Finanças II'!C19,"—") | D7: =IF(C7="—","—",IF(C7>=5,"✓ Aprovado","Em andamento")) | E7: 26/05/2026
A8: HPE | B8: P.Duarte / F.Leite | C8: =IF(ISNUMBER('HPE'!C59),'HPE'!C59,"—") | D8: =IF(C8="—","—",IF(C8>=5,"✓ Aprovado","Em andamento")) | E8: 28/05/2026
A9: Macro Internacional | B9: G.Olivares / G.Duarte | C9: =IF(ISNUMBER('Macro Internacional'!C19),'Macro Internacional'!C19,"—") | D9: =IF(C9="—","—",IF(C9>=5,"✓ Aprovado","Em andamento")) | E9: 27/05/2026
A10: Micro II | B10: Darcio / G.Carvalho | C10: =IF(ISNUMBER('Micro II'!C21),'Micro II'!C21,"—") | D10: =IF(C10="—","—",IF(C10>=5,"✓ Aprovado","Em andamento")) | E10: 27/05/2026
A11: Micro III | B11: I.Furtado / F.Rosa | C11: =IF(ISNUMBER('Micro III'!C54),'Micro III'!C54,"—") | D11: =IF(C11="—","—",IF(C11>=5,"✓ Aprovado","Em andamento")) | E11: 27/05/2026
A13: Acesse cada aba para inserir notas. Células amarelas = entrada manual. Cinzas = calculado.

Sheet Econometria
A1: ECONOMETRIA — Controle de Notas
A2: Prof. Adriana Bortoluzzo / Sérgio Martins | Turma 4ECOB | Qua 16:30–18:30 / Sex 14:15–16:15
A3: MP=0,40·AI+0,60·AF | MF=MP se MP<4 | MF=0,75·MP+0,15·MQ+0,10·APS se MP≥4
A4: Aprovação: MF≥5,0 | APS zero = REPROVAÇÃO AUTOMÁTICA
A6: ▼ INSIRA SUAS NOTAS (células amarelas)
A7: Avaliação | B7: Data | C7: Nota | D7: Observações
A8: Avaliação Intermediária (AI) — 30% (via MP) | B8: 25/03/2026
A9: Quiz 1 — para MQ | B9: 11/03/2026
A10: Quiz 2 — para MQ | B10: 20/03/2026
A11: Quiz 3 — para MQ | B11: 08/05/2026 | D11: Média dos 3 quizzes = MQ (15%)
A12: APS — Atividade em Aula (10%) | B12: ao longo | D12: Nota zero = reprovação
A13: Avaliação Final (AF) — 45% (via MP) | B13: 27/05/2026
A15: ▼ CALCULADO AUTOMATICAMENTE (não editar)
A16: MQ (Média dos Quizzes) | C16: =IFERROR(AVERAGE(C9:C11),"—") | D16: Média simples de Q1, Q2, Q3
A17: MP (Média das Provas) | C17: =IF(OR(NOT(ISNUMBER(C8)),NOT(ISNUMBER(C13))),"",0.4*C8+0.6*C13) | D17: 0,40·AI + 0,60·AF
A18: MF (Média Final) | C18: =IF(C17="","",IF(C17<4,C17,0.75*C17+0.15*IF(ISNUMBER(C16),C16,0)+0.1*IF(ISNUMBER(C12),C12,0))) | D18: Fórmula condicional (MP≥4)
A19: Situação atual | C19: =IF(C18="","Aguardando notas...",IF(C18>=5,"✓ APROVADO DIRETO!","Em andamento — veja simulação"))
A21: ▼ SIMULAÇÃO — O QUE PRECISO PARA PASSAR?
A22: Nota necessária na AF (dados atuais) | B22: Brancos = 0 (pior caso) | C22: =IF(NOT(ISNUMBER(C8)),"Preencha a AI primeiro",IF(F22<=0,"✓ Aprovado direto!",IF(F22>10,"✗ Reprovado mesmo com 10 na AF","Precisa de "&TEXT(ROUND(F22,2),"0.00")&" na AF"))) | F22: =IF(NOT(ISNUMBER(C8)),-999,MAX((5-0.3*C8-0.15*IF(ISNUMBER(C16),C16,0)-0.1*IF(ISNUMBER(C12),C12,0))/0.45,(4-0.4*C8)/0.6))

Sheet Estatística II
A1: ESTATÍSTICA II — Controle de Notas
A2: Prof. Maria Kelly Venezuela / Rinaldo Artes | Turma 3DPA | Qua 19:00–21:00 / Sex 19:00–21:00
A3: MP=0,35·PI+0,65·PF | MA=0,50·APS1+0,50·APS2 | MF=MP(MP<4) ou 0,80·MP+0,20·MA(MP≥4)
A4: Aprovação: MF≥5,0 | Não entregar NENHUMA APS = REPROVAÇÃO AUTOMÁTICA
A6: ▼ INSIRA SUAS NOTAS (células amarelas)
A7: Avaliação | B7: Data | C7: Nota | D7: Observações
A8: PI — Prova Intermediária (35% do MP) | B8: 25/03/2026
A9: APS 1 — 50% da MA | B9: 13/03/2026 | D9: Realizada em sala, individual
A10: APS 2 — 50% da MA | B10: 29/04/2026 | D10: Realizada em sala, individual
A11: PF — Prova Final (65% do MP) | B11: 27/05/2026
A13: ▼ CALCULADO AUTOMATICAMENTE (não editar)
A14: MA (Média das APS) | C14: =IF(AND(ISNUMBER(C9),ISNUMBER(C10)),0.5*C9+0.5*C10,IF(ISNUMBER(C9),C9,IF(ISNUMBER(C10),C10,"—"))) | D14: 0,50·APS1+0,50·APS2
A15: MP (Média das Provas) | C15: =IF(OR(NOT(ISNUMBER(C8)),NOT(ISNUMBER(C11))),"",0.35*C8+0.65*C11) | D15: 0,35·PI+0,65·PF
A16: MF (Média Final) | C16: =IF(C15="","",IF(C15<4,C15,0.8*C15+0.2*IF(ISNUMBER(C14),C14,0))) | D16: Condicional em MP≥4
A17: Situação atual | C17: =IF(C16="","Aguardando notas...",IF(C16>=5,"✓ APROVADO DIRETO!","Em andamento — veja simulação"))
A19: ▼ SIMULAÇÃO — O QUE PRECISO PARA PASSAR?
A20: Nota necessária na PF (dados atuais) | B20: Brancos = 0 (pior caso) | C20: =IF(NOT(ISNUMBER(C8)),"Preencha a PI primeiro",IF(F20<=0,"✓ Aprovado direto!",IF(F20>10,"✗ Reprovado mesmo com 10 na PF","Precisa de "&TEXT(ROUND(F20,2),"0.00")&" na PF"))) | F20: =IF(NOT(ISNUMBER(C8)),-999,MAX((5-0.28*C8-0.2*IF(ISNUMBER(C14),C14,0))/0.52,(4-0.35*C8)/0.65))

Sheet Finanças II
A1: FINANÇAS II — Controle de Notas
A2: Prof. Gustavo Soares / Paulo Neto | Turma 4ECOB | Ter 14:15–16:15 / Sex 09:45–11:45
A3: MF = 0,30·PI + 0,20·MQ + 0,40·PF + 0,10·APS | MQ = média dos 4 melhores quizzes (de 5)
A4: Aprovação: MF≥5,0 | APS zero = REPROVAÇÃO AUTOMÁTICA
A6: ▼ INSIRA SUAS NOTAS (células amarelas)
A7: Avaliação | B7: Data | C7: Nota | D7: Observações
A8: PI — Prova Intermediária (30%) | B8: 24/02/2026
A9: Quiz 1 (para MQ) | B9: 24/02/2026
A10: Quiz 2 (para MQ) | B10: 10/03/2026
A11: Quiz 3 (para MQ) | B11: 07/04/2026
A12: Quiz 4 (para MQ) | B12: 05/05/2026
A13: Quiz 5 (para MQ) | B13: 19/05/2026 | D13: Descarta o pior dos 5
A14: APS — Ativ. Pedagógica (10%) | B14: ao longo | D14: Nota zero = reprovação
A15: PF — Prova Final (40%) | B15: 26/05/2026
A17: ▼ CALCULADO AUTOMATICAMENTE (não editar)
A18: MQ (Média dos 4 melhores quizzes) | C18: =IF(COUNT(C9:C13)=0,"—",IF(COUNT(C9:C13)=1,AVERAGE(C9:C13),(SUM(C9:C13)-MIN(C9:C13))/MAX(COUNT(C9:C13)-1,1))) | D18: Descarta 1 pior dos 5
A19: MF (Média Final) | C19: =IF(OR(NOT(ISNUMBER(C8)),NOT(ISNUMBER(C15))),"",0.3*C8+0.2*IF(ISNUMBER(C18),C18,0)+0.4*C15+0.1*IF(ISNUMBER(C14),C14,0)) | D19: 0,30·PI+0,20·MQ+0,40·PF+0,10·APS
A20: Situação atual | C20: =IF(C19="","Aguardando notas...",IF(C19>=5,"✓ APROVADO DIRETO!","Em andamento — veja simulação"))
A22: ▼ SIMULAÇÃO — O QUE PRECISO PARA PASSAR?
A23: Nota necessária na PF (dados atuais) | B23: Brancos = 0 (pior caso) | C23: =IF(NOT(ISNUMBER(C8)),"Preencha a PI primeiro",IF(F23<=0,"✓ Aprovado direto!",IF(F23>10,"✗ Reprovado mesmo com 10 na PF","Precisa de "&TEXT(ROUND(F23,2),"0.00")&" na PF"))) | F23: =IF(NOT(ISNUMBER(C8)),-999,(5-0.3*C8-0.2*IF(ISNUMBER(C18),C18,0)-0.1*IF(ISNUMBER(C14),C14,0))/0.4)

Sheet HPE
A1: HPE — História do Pensamento Econômico
A2: Prof. Pedro Duarte / Fernando Leite Neto | Turma 4ECOB | Ter 16:30–18:30 / Qui 07:30–09:30
A3: MF=0,25·PI+0,35·PF+0,15·APS+0,20·AA+0,05·PE | Notas AA/PE: -1, 0 ou +1
A4: Aprovação: MF≥5,0 E (PI+PF)/2≥4,5 | APS zero = REPROVAÇÃO AUTOMÁTICA
A6: ▼ INSIRA SUAS NOTAS (células amarelas)
A7: Avaliação | B7: Data | C7: Nota | D7: Observações
A8: PI — Prova Intermediária (25%) | B8: 26/03/2026
A9: PF — Prova Final (35%) | B9: 28/05/2026
A10: APS — Ativ. Prática (15%) | B10: ao longo | D10: 2 APS no semestre; nota zero = reprovação
A12: ▼ ATIVIDADES DE APRENDIZAGEM (AA) — insira -1, 0 ou +1 nas células amarelas
A13: Aula/Data | B13: Tópico | C13: Nota (-1/0/+1) | D13: Obs
A14: AA 1
A15: AA 2
A16: AA 3
A17: AA 4
A18: AA 5
A19: AA 6
A20: AA 7
A21: AA 8
A22: AA 9
A23: AA 10
A24: AA 11
A25: AA 12
... A35: ▼ PERGUNTAS SOBRE APRESENTAÇÕES (PE) — insira -1, 0 ou +1
A36: Aula/Data | B36: Tópico | C36: Nota (-1/0/+1) | D36: Obs
A37: PE 1
A38: PE 2
A39: PE 3
A40: PE 4
A41: PE 5
A42: PE 6
A43: PE 7
A44: PE 8
A45: PE 9
A46: PE 10
A47: PE 11
A48: PE 12
... A53: ▼ CALCULADO AUTOMATICAMENTE (não editar)
A54: Média AA (após descarte do pior) | C54: =IF(COUNT(C14:C33)=0,"—",IF(COUNT(C14:C33)>=2,(SUM(C14:C33)-MIN(C14:C33))/(COUNT(C14:C33)-1),AVERAGE(C14:C33))) | D54: Descarta 1 se ≥2 AA feitas
A55: Nota AA (escala 0–12) | C55: =IF(C54="—","—",IF(C54<=-0.75,0,IF(C54<=-0.501,2,IF(C54<=-0.01,4,IF(C54<=0.19,6,IF(C54<=0.39,8,IF(C54<=0.59,10,12))))))) | D55: Tabela de conversão do plano
...

Sheet Macro Internacional
A1: MACROECONOMIA INTERNACIONAL — Controle de Notas
A2: Prof. Gino Olivares / Guilherme Duarte | Turma 4ECOB | Seg 16:30–18:30 / Qua 09:45–11:45
A3: MPP=0,40·AI+0,50·AF+0,10·APS | MSP=(AI+AF)/2 | MF=MSP(MSP<4,5) ou MPP(MSP≥4,5)
A4: Aprovação: MSP≥4,5 E MF≥5,0 | APS zero = REPROVAÇÃO AUTOMÁTICA
A6: ▼ INSIRA SUAS NOTAS (células amarelas)
A7: Avaliação | B7: Data | C7: Nota | D7: Observações
A8: AI — Avaliação Intermediária (40%) | B8: 25/03/2026
A9: APS 1 — 1ª de 4 (média 3 maiores) | B9: 04/03/2026
A10: APS 2 | B10: 11/03/2026
A11: APS 3 | B11: 27/04/2026
A12: APS 4 | B12: 13/05/2026 | D12: Descarta a menor das 4
A13: AF — Avaliação Final (50%) | B13: 27/05/2026
A15: ▼ CALCULADO AUTOMATICAMENTE (não editar)
A16: APS média (3 maiores de 4) | C16: =IF(COUNT(C9:C12)=0,"—",IF(COUNT(C9:C12)<4,AVERAGE(C9:C12),(LARGE(C9:C12,1)+LARGE(C9:C12,2)+LARGE(C9:C12,3))/3)) | D16: Descarta a menor APS das 4
A17: MSP = (AI+AF)/2 | C17: =IF(OR(NOT(ISNUMBER(C8)),NOT(ISNUMBER(C13))),"",( C8+C13)/2) | D17: Mínimo 4,5 p/ usar MPP
A18: MPP (Média Ponderada) | C18: =IF(OR(NOT(ISNUMBER(C8)),NOT(ISNUMBER(C13))),"",0.4*C8+0.5*C13+0.1*IF(ISNUMBER(C16),C16,0)) | D18: 0,40·AI+0,50·AF+0,10·APS
A19: MF (Média Final) | C19: =IF(C17="","",IF(C17<4.5,C17,C18)) | D19: MSP<4,5→MF=MSP; senão MF=MPP
A20: Situação atual | C20: =IF(C19="","Aguardando notas...",IF(C19>=5,"✓ APROVADO DIRETO!","Em andamento — veja simulação"))
A22: ▼ SIMULAÇÃO — O QUE PRECISO PARA PASSAR?
A23: Nota necessária na AF (dados atuais) | B23: Brancos = 0 (pior caso) | C23: =IF(NOT(ISNUMBER(C8)),"Preencha a AI primeiro",IF(F23<=0,"✓ Aprovado direto!",IF(F23>10,"✗ Reprovado mesmo com 10 na AF","Precisa de "&TEXT(ROUND(F23,2),"0.00")&" na AF"))) | F23: =IF(NOT(ISNUMBER(C8)),-999,MAX(9-C8,(5-0.4*C8-0.1*IF(ISNUMBER(C16),C16,0))/0.5))

Sheet Micro II
A1: MICROECONOMIA II — Controle de Notas
A2: Prof. Darcio Martins / Guilherme Carvalho | Turma 3D | Seg 14:15–16:15 / Qua 14:15–16:15
A3: MF = 0,10·Q + 0,10·APS + 0,30·AI + 0,50·AF | Q = média simples de 6 quizzes
A4: Aprovação: MF≥5,0 E (AI+AF)/2≥4,0
A6: ▼ INSIRA SUAS NOTAS (células amarelas)
A7: Avaliação | B7: Data | C7: Nota | D7: Observações
A8: AI — Avaliação Intermediária (30%) | B8: 30/03/2026
A9: Quiz 1 | B9: 04/03/2026
A10: Quiz 2 | B10: 11/03/2026
A11: Quiz 3 | B11: 23/03/2026
A12: Quiz 4 | B12: 15/04/2026
A13: Quiz 5 | B13: 06/05/2026
A14: Quiz 6 | B14: 20/05/2026 | D14: Sem descarte — média dos 6
A15: APS — Ativ. Prática (10%) | B15: ao longo
A16: AF — Avaliação Final (50%) | B16: 27/05/2026
A18: ▼ CALCULADO AUTOMATICAMENTE (não editar)
A19: MQ (Média dos 6 Quizzes) | C19: =IFERROR(AVERAGE(C9:C14),"—") | D19: Média simples, sem descarte
A20: MSP = (AI+AF)/2 | C20: =IF(OR(NOT(ISNUMBER(C8)),NOT(ISNUMBER(C16))),"",( C8+C16)/2) | D20: Mínimo 4,0 p/ aprovação
A21: MF (Média Final) | C21: =IF(OR(NOT(ISNUMBER(C8)),NOT(ISNUMBER(C16))),"",0.1*IF(ISNUMBER(C19),C19,0)+0.1*IF(ISNUMBER(C15),C15,0)+0.3*C8+0.5*C16) | D21: 0,10·Q+0,10·APS+0,30·AI+0,50·AF
A22: Situação atual | C22: =IF(C21="","Aguardando notas...",IF(AND(C21>=5,IF(C20="",0,C20)>=4),"✓ APROVADO DIRETO!","Em andamento — veja simulação"))
A24: ▼ SIMULAÇÃO — O QUE PRECISO PARA PASSAR?
A25: Nota necessária na AF (dados atuais) | B25: Brancos = 0 (pior caso) | C25: =IF(NOT(ISNUMBER(C8)),"Preencha a AI primeiro",IF(F25<=0,"✓ Aprovado direto!",IF(F25>10,"✗ Reprovado mesmo com 10 na AF","Precisa de "&TEXT(ROUND(F25,2),"0.00")&" na AF"))) | F25: =IF(NOT(ISNUMBER(C8)),-999,MAX(8-C8,(5-0.1*IF(ISNUMBER(C19),C19,0)-0.1*IF(ISNUMBER(C15),C15,0)-0.3*C8)/0.5))

Sheet Micro III
A1: MICROECONOMIA III — Controle de Notas
A2: Prof. Isabela Furtado / Fabio Rosa | Turma 4ECOB | Seg 09:45–11:45 / Qui 12:00–14:00
A3: MF=0,35·PI+0,40·PF+0,10·QZ+0,10·APS+0,05·PA | QZ=3 melhores de 4 quizzes
A4: Aprovação: MF≥5,0 | PA: descarta 5 piores notas
A6: ▼ INSIRA SUAS NOTAS (células amarelas)
A7: Avaliação | B7: Data | C7: Nota | D7: Observações
A8: PI — Prova Intermediária (35%) | B8: 30/03/2026
A9: Quiz 1 (para QZ) | B9: 02/03/2026
A10: Quiz 2 (para QZ) | B10: 23/03/2026
A11: Quiz 3 (para QZ) | B11: 30/04/2026
A12: Quiz 4 (para QZ) | B12: 14/05/2026 | D12: Descarta 1 pior → média dos 3 melhores
A13: APS 1 — Caso (10%) | B13: 16/04/2026 | D13: 50% particip sala + 50% entrega
A14: APS 2 — Caso | B14: 21/05/2026 | D14: Média de APS1 e APS2 = APS
A15: PF — Prova Final (40%) | B15: 27/05/2026
A17: ▼ PARTICIPAÇÃO (PA) — insira 0, 5 ou 10 em cada aula (células amarelas)
A18: Aula | B18: Data | C18: Nota (0/5/10) | D18: Obs
A19: Aula 1
A20: Aula 2
A21: Aula 3
A22: Aula 4
A23: Aula 5
A24: Aula 6
A25: Aula 7
A26: Aula 8
A27: Aula 9
A28: Aula 10
A29: Aula 11
A30: Aula 12
... A50: ▼ CALCULADO AUTOMATICAMENTE (não editar)
A51: QZ (3 melhores quizzes de 4) | C51: =IF(COUNT(C9:C12)=0,"—",IF(COUNT(C9:C12)<=3,AVERAGE(C9:C12),(LARGE(C9:C12,1)+LARGE(C9:C12,2)+LARGE(C9:C12,3))/3)) | D51: Descarta o pior dos 4 quizzes
A52: APS (média APS1 e APS2) | C52: =IF(AND(ISNUMBER(C13),ISNUMBER(C14)),AVERAGE(C13:C14),IF(ISNUMBER(C13),C13,IF(ISNUMBER(C14),C14,"—"))) | D52: Média de 2 casos
A53: PA média (descarta 5 piores) | C53: =IF(COUNT(C19:C48)=0,"—",IF(COUNT(C19:C48)<=5,AVERAGE(C19:C48),(SUM(C19:C48)-SUMPRODUCT(SMALL(C19:C48,ROW(INDIRECT("1:5")))))/MAX(COUNT(C19:C48)-5,1))) | D53: Descarta 5 piores participações
A54: MF (Média Final) | C54: =IF(OR(NOT(ISNUMBER(C8)),NOT(ISNUMBER(C15))),"",0.35*C8+0.40*C15+0.10*IF(ISNUMBER(C51),C51,0)+0.10*IF(ISNUMBER(C52),C52,0)+0.05*IF(ISNUMBER(C53),C53,0)) | D54: 0,35·PI+0,40·PF+0,10·QZ+0,10·APS+0,05·PA
A55: Situação atual | C55: =IF(C54="","Aguardando notas...",IF(C54>=5,"✓ APROVADO DIRETO!","Em andamento — veja simulação"))
A57: ▼ SIMULAÇÃO — O QUE PRECISO PARA PASSAR?
A58: Nota necessária na PF (dados atuais) | B58: Brancos = 0 (pior caso) | C58: =IF(NOT(ISNUMBER(C8)),"Preencha a PI primeiro",IF(F58<=0,"✓ Aprovado direto!",IF(F58>10,"✗ Reprovado mesmo com 10 na PF","Precisa de "&TEXT(ROUND(F58,2),"0.00")&" na PF"))) | F58: =IF(NOT(ISNUMBER(C8)),-999,(5-0.35*C8-0.10*IF(ISNUMBER(C51),C51,0)-0.10*IF(ISNUMBER(C52),C52,0)-0.05*IF(ISNUMBER(C53),C53,0))/0.40)
